Workbook

Sheet Script Inventory
B2: SandBox
C3: AuthAPI | D3: =COUNTA(SBAuthAPI!E:E)-1 -> 26
C4: BankList | D4: =COUNTA(SBBankList!E:E)-1 -> 18
C5: CheckStatus | D5: =COUNTA(SBCheckStatus!E:E)-1 -> 60
C6: LFT | D6: =COUNTA(SBSendFunds!E:E)-1 -> 114
D7: =SUM(D3:D6) -> 218
B8: Test
C9: AuthAPI | D9: =COUNTA(PTTAuthAPI!E:E)-1 -> 27
C10: BankList | D10: =COUNTA(PTTBankList!E:E)-1 -> 19
C11: CheckStatus | D11: =COUNTA(PTTCheckStatus!E:E)-1 -> 59
C12: LFT | D12: =COUNTA(PTTSendFunds!E:E)-1 -> 230
D13: =SUM(D9:D12) -> 335
B14: Live
C15: AuthAPI | D15: =COUNTA(PTLAuthAPI!E:E)-1 -> 26
C16: BankList | D16: =COUNTA(PTLBankList!E:E)-1 -> 19
C17: CheckStatus | D17: =COUNTA(PTLCheckStatus!E:E)-1 -> 56
C18: LFT | D18: =COUNTA(PTLSendFunds!E:E)-1 -> 302
D19: =SUM(D15:D18) -> 403
C22: Overall Count | D22: =SUM(D7,D13,D19) -> 956

Sheet Legend
B2: Legend: | E2: Live
C3: Not Applicable | E3: hemPVxAxU8QC6QlJuS5GQoPiP0dFdBzP | F3: Client ID
C4: Valid Test Data Value | E4: pLRFPZKifoRD00dj761QToHciekWqbbh | F4: Client Secret
C5: Invalid Headers/Body | E5: KPEgf6fjIHDaT0HByFjWD49cQWdphJMM | F5: API Key
C6: Blocked TC | F6: Partner ID
C7: Undecided
C8: 200 OK But Transaction expected to Failed on Check Status | E8: Test
C9: Test Case can be confirmed using the previous test cases/ Related Test Case | E9: 3TaenF9h5d9FCEEIZRVPc4AxdFggPaxA | F9: Client ID
C10: Need to Add Cells for Additional parameters (body) | E10: wE4n0CYiVOdJ9m8EfKuMhxm0m4kOaUOr | F10: Client Secret
E11: K6y28Ks1TyrwjONU0PatZ6BhOWfTAuHo | F11: API Key
F12: Partner ID

Sheet SBAuthAPI
A1: # | B1: ExecutionFlag | C1: CORE | D1: TC_ID | E1: Description | F1: StepAction | G1: ExpectedResult | H1: ExpectedStatus | I1: ExpectedResponseDescription | J1: IN_EndPoint | K1: IN_HeadAccept | L1: IN_HeadClientID | M1: IN_HeadClientSecret | N1: IN_HeadPartnerID | O1: IN_HeadAPIKey | P1: IN_HeadContentType | Q1: IN_AccountNumber | R1: IN_Scope | S1: OUT_RequestHeaders | T1: OUT_RequestBody | U1: OUT_ResponseHeaders | V1: OUT_ResponseBody
A2: 1 | B2: Y | C2: Y | D2: TS-EB-SB-PRODUCTS-0102 | E2: TS-EB-SB-PRODUCTS-0102: Account Authentication via Access Token v1.0_Generate Account Access Token API_Verify Token generation for Client-Owned Account | F2: Send POST Request using Client-Owned Account | G2: Successful Request Status 200 OK Response Body contains: - access_token [Token is valid and usable] - token_type - expires_in -authId Request logged in API Portal DB | H2: 200 | J2: /auth/token/v1/generate | K2: application/json | L2: 1VjIqTcMCJ8tIv8bMpv9l9x01ebYQd88 | M2: cnfKqb1Q53rmlS8HifRZf7zvtGZOSlUQ | N2: 104234abc4 | O2: GsG5c0UhuhXUPj4XlY8G1kcjKioiFrqI | P2: application/json | Q2: 200061777902 | R2: send-funds.initiate
A3: 2 | B3: Y | C3: Y | D3: TS-EB-SB-PRODUCTS-0103_1 | E3: TS-EB-SB-PRODUCTS-0103_1: Account Authentication via Access Token v1.0_Generate Account Access Token API_Verify send request with missing mandatory parameters. | F3: Send POST Request with missing mandatory parameters | G3: Failed 400 (Bad Request) Error details for missing fields Response Body contains: - access_token [Token is valid and usable] - token_type - expires_in -authId | H3: 400 | I3: The scope provided is invalid or not recognized | J3: /auth/token/v1/generate | K3: application/json | L3: 1VjIqTcMCJ8tIv8bMpv9l9x01ebYQd88 | M3: cnfKqb1Q53rmlS8HifRZf7zvtGZOSlUQ | N3: 104234abc4 | O3: GsG5c0UhuhXUPj4XlY8G1kcjKioiFrqI | P3: application/json | Q3: 200061777902
A4: 3 | B4: Y | C4: Y | D4: TS-EB-SB-PRODUCTS-0103_2 | E4: TS-EB-SB-PRODUCTS-0103_2: Account Authentication via Access Token v1.0_Generate Account Access Token API_Verify send request with missing mandatory parameters. | F4: Send POST Request with missing mandatory parameters | G4: Failed 400 (Bad Request) Error details for missing fields | H4: 400 | I4: The accountNumber provided is invalid, not recognized, or not registered in Client Hub. | J4: /auth/token/v1/generate | K4: application/json | L4: 1VjIqTcMCJ8tIv8bMpv9l9x01ebYQd88 | M4: cnfKqb1Q53rmlS8HifRZf7zvtGZOSlUQ | N4: 104234abc4 | O4: GsG5c0UhuhXUPj4XlY8G1kcjKioiFrqI | P4: application/json | R4: send-funds.initiate
A5: 4 | B5: Y | C5: Y | D5: TS-EB-SB-PRODUCTS-0105 | E5: TS-EB-SB-PRODUCTS-0105: Account Authentication via Access Token v1.0_Generate Account Access Token API_Verify successful POST Authentication using Client Owned Account with ACTIVE status and with valid client-id, client-secret, and partner-id | F5: Send POST Request using valid ACTIVE Client Owned Account wiht valid client-credentials | G5: Successful Status 200 OK Response Body: within 300 ms. accessToken, tokenType: Bearer, expiresIn, authId Token is bound to the exact account, | H5: 200 | J5: /auth/token/v1/generate | K5: application/json | L5: 1VjIqTcMCJ8tIv8bMpv9l9x01ebYQd88 | M5: cnfKqb1Q53rmlS8HifRZf7zvtGZOSlUQ | N5: 104234abc4 | O5: GsG5c0UhuhXUPj4XlY8G1kcjKioiFrqI | P5: application/json | Q5: 200061777902 | R5: send-funds.initiate
A6: 5 | B6: Y | C6: Y | D6: TS-EB-SB-PRODUCTS-0107 | E6: TS-EB-SB-PRODUCTS-0107: Account Authentication via Access Token v1.0_Generate Account Access Token API_Verify authentication token is usable in the next account-based API call within the expiry window | F6: Send POST Request using valid ACTIVE Client Owned Account with valid client-credentials using same authentication token | G6: Token generated is usable in the nexy account-based transactional API call within expiry (3600s) | H6: 200 | J6: /auth/token/v1/generate | K6: application/json | L6: 1VjIqTcMCJ8tIv8bMpv9l9x01ebYQd88 | M6: cnfKqb1Q53rmlS8HifRZf7zvtGZOSlUQ | N6: 104234abc4 | O6: GsG5c0UhuhXUPj4XlY8G1kcjKioiFrqI | P6: application/json | Q6: 200061777902 | R6: send-funds.initiate
A7: 6 | B7: Y | C7: Y | D7: TS-EB-SB-PRODUCTS-0108_1 | E7: TS-EB-SB-PRODUCTS-0108_1: Account Authentication via Access Token v1.0_Generate Account Access Token API_Verify POST request using Invalid client credentials | F7: Send POST Request using valid ACTIVE Client Owned Account with invalid client-credentials | G7: Failed/ Rejected Request 401 Unauthorized No token generated, authid, redirectUrl are returned Invalid credential attempts are rejected within 300 ms. | H7: 401 | I7: Invalid OAuth2 request parameters | J7: /auth/token/v1/generate | K7: application/json | L7: 1VjIqTcMCJ8tIv8bMpv9i9x01ebYQd32 | M7: cnfKqb1Q53rmlS8HifRZf7zvtGZOSlUQ | N7: 104234abc4 | O7: GsG5c0UhuhXUPj4XlY8G1kcjKioiFrqI | P7: application/json | Q7: 200061777902 | R7: send-funds.initiate
A8: 7 | B8: Y | C8: Y | D8: TS-EB-SB-PRODUCTS-0108_2 | E8: TS-EB-SB-PRODUCTS-0108_2: Account Authentication via Access Token v1.0_Generate Account Access Token API_Verify POST request using Invalid client credentials | F8: Send POST Request using valid ACTIVE Client Owned Account with invalid client-credentials | G8: Failed/ Rejected Request 401 Unauthorized No token generated, authid, redirectUrl are returned Invalid credential attempts are rejected within 300 ms. | H8: 401 | I8: Invalid OAuth2 request parameters | J8: /auth/token/v1/generate | K8: application/json | L8: 1VjIqTcMCJ8tIv8bMpv9l9x01ebYQd88 | M8: cnfKqj1Q53rmlS8HifRZf7zvtGZOSlUW | N8: 104234abc4 | O8: GsG5c0UhuhXUPj4XlY8G1kcjKioiFrqI | P8: application/json | Q8: 200061777902 | R8: send-funds.initiate
A9: 8 | B9: Y | C9: Y | D9: TS-EB-SB-PRODUCTS-0108_3 | E9: TS-EB-SB-PRODUCTS-0108_3: Account Authentication via Access Token v1.0_Generate Account Access Token API_Verify POST request using Invalid client credentials | F9: Send POST Request using valid ACTIVE Client Owned Account with invalid client-credentials | G9: Failed/ Rejected Request 401 Unauthorized No token generated, authid, redirectUrl are returned Invalid credential attempts are rejected within 300 ms. | H9: 401 | I9: Invalid OAuth2 request parameters | J9: /auth/token/v1/generate | K9: application/json | M9: cnfKqb1Q53rmlS8HifRZf7zvtGZOSlUQ | N9: 104234abc4 | O9: GsG5c0UhuhXUPj4XlY8G1kcjKioiFrqI | P9: application/json | Q9: 200061777902 | R9: send-funds.initiate
A10: 9 | B10: Y | C10: Y | D10: TS-EB-SB-PRODUCTS-0108_4 | E10: TS-EB-SB-PRODUCTS-0108_4: Account Authentication via Access Token v1.0_Generate Account Access Token API_Verify POST request using Invalid client credentials | F10: Send POST Request using valid ACTIVE Client Owned Account with invalid client-credentials | G10: Failed/ Rejected Request 401 Unauthorized No token generated, authid, redirectUrl are returned Invalid credential attempts are rejected within 300 ms. | H10: 401 | I10: Invalid OAuth2 request parameters | J10: /auth/token/v1/generate | K10: application/json | L10: 1VjIqTcMCJ8tIv8bMpv9l9x01ebYQd88 | N10: 104234abc4 | O10: GsG5c0UhuhXUPj4XlY8G1kcjKioiFrqI | P10: application/json | Q10: 200061777902 | R10: send-funds.initiate
A11: 10 | B11: Y | C11: Y | D11: TS-EB-SB-PRODUCTS-0109 | E11: TS-EB-SB-PRODUCTS-0109: Account Authentication via Access Token v1.0_Generate Account Access Token API_Verify if POST request with Invalid Client credentials is logged in API Portal Database | F11: Send POST Request using valid ACTIVE Client Owned Account with invalid client-credentials. Validate DB | G11: Security event is logged in the API Portal Database. | H11: 200 | J11: /auth/token/v1/generate | K11: application/json | L11: 1VjIqTcMCJ8tIv8bMpv9l9x01ebYQd88 | M11: cnfKqb1Q53rmlS8HifRZf7zvtGZOSlUQ | N11: 104234abc4 | O11: GsG5c0UhuhXUPj4XlY8G1kcjKioiFrqI | P11: application/json | Q11: 200061777902 | R11: send-funds.initiate
A12: 11 | B12: Y | C12: Y | D12: TS-EB-SB-PRODUCTS-0110_1 | E12: TS-EB-SB-PRODUCTS-0110_1: Account Authentication via Access Token v1.0_Generate Account Access Token API_Verify Send Request using Invalid Account Number | F12: Send POST Request using Invalid Client Owned Account with valid client-credentials. | G12: Failed / Rejected Request 400 Bad Request - error code invalid_account - clear errorDescription. No token or redirectUrl is issued. Core banking validation completes and rejects within 300 ms. | H12: 400 | I12: The accountNumber provided is invalid, not recognized, or not registered in Client Hub. | J12: /auth/token/v1/generate | K12: application/json | L12: 1VjIqTcMCJ8tIv8bMpv9l9x01ebYQd88 | M12: cnfKqb1Q53rmlS8HifRZf7zvtGZOSlUQ | N12: 104234abc4 | O12: GsG5c0UhuhXUPj4XlY8G1kcjKioiFrqI | P12: application/json | Q12: 200061977902 | R12: send-funds.initiate
A13: 12 | B13: Y | C13: Y | D13: TS-EB-SB-PRODUCTS-0110_2 | E13: TS-EB-SB-PRODUCTS-0110_2: Account Authentication via Access Token v1.0_Generate Account Access Token API_Verify Send Request using Invalid Account Number | F13: Send POST Request using Invalid Client Owned Account with valid client-credentials. | G13: Failed / Rejected Request 400 Bad Request - error code invalid_account - clear errorDescription. No token or redirectUrl is issued. Core banking validation completes and rejects within 300 ms. | H13: 400 | I13: The accountNumber provided is invalid, not recognized, or not registered in Client Hub. | J13: /auth/token/v1/generate | K13: application/json | L13: 1VjIqTcMCJ8tIv8bMpv9l9x01ebYQd88 | M13: cnfKqb1Q53rmlS8HifRZf7zvtGZOSlUQ | N13: 104234abc4 | O13: GsG5c0UhuhXUPj4XlY8G1kcjKioiFrqI | P13: application/json | R13: send-funds.initiate
A14: 13 | B14: Y | C14: Y | D14: TS-EB-SB-PRODUCTS-0111 | E14: TS-EB-SB-PRODUCTS-0111: Account Authentication via Access Token v1.0_Generate Account Access Token API_Verify Send Request using Inactive Account Number | F14: Send POST Request using INACTIVE Client Owned Account with valid client-credentials. | G14: Failed / Rejected Request 400 Bad Request - error code account_inactive - clear errorDescription. No token or redirectUrl is issued. Core banking validation completes and rejects within 300 ms. | H14: 400 | I14: The accountNumber provided is invalid, not recognized, or not registered in Client Hub. | J14: /auth/token/v1/generate | K14: application/json | L14: 1VjIqTcMCJ8tIv8bMpv9l9x01ebYQd88 | M14: cnfKqb1Q53rmlS8HifRZf7zvtGZOSlUQ | N14: 104234abc4 | O14: GsG5c0UhuhXUPj4XlY8G1kcjKioiFrqI | P14: application/json | Q14: 200098777902 | R14: send-funds.initiate
A15: 14 | B15: Y | C15: Y | D15: TS-EB-SB-PRODUCTS-0112 | E15: TS-EB-SB-PRODUCTS-0112: Account Authentication via Access Token v1.0_Generate Account Access Token API_Verify Send Request using Not Existing Account Number | F15: Send POST Request using NOT EXISTING Client Owned Account with valid client-credentials. | G15: Failed / Rejected Request 400 Bad Request - error code invalid_account - clear errorDescription. No token or redirectUrl is issued. Core banking validation completes and rejects within 300 ms. | H15: 400 | I15: The accountNumber provided is invalid, not recognized, or not registered in Client Hub. | J15: /auth/token/v1/generate | K15: application/json | L15: 1VjIqTcMCJ8tIv8bMpv9l9x01ebYQd88 | M15: cnfKqb1Q53rmlS8HifRZf7zvtGZOSlUQ | N15: 104234abc4 | O15: GsG5c0UhuhXUPj4XlY8G1kcjKioiFrqI | P15: application/json | Q15: 200081579910 | R15: send-funds.initiate
A16: 15 | B16: Y | C16: Y | D16: TS-EB-SB-PRODUCTS-0113 | E16: TS-EB-SB-PRODUCTS-0113: Account Authentication via Access Token v1.0_Generate Account Access Token API_Verify Send Request using Malformed Account Number | F16: Send POST Request using MALFORMED Client Owned Account with valid client-credentials. | G16: Failed / Rejected Request 400 Bad Request - error code invalid_account - clear errorDescription. No token or redirectUrl is issued. Core banking validation completes and rejects within 300 ms. | H16: 400 | I16: The accountNumber provided is invalid, not recognized, or not registered in Client Hub. | J16: /auth/token/v1/generate | K16: application/json | L16: 1VjIqTcMCJ8tIv8bMpv9l9x01ebYQd88 | M16: cnfKqb1Q53rmlS8HifRZf7zvtGZOSlUQ | N16: 104234abc4 | O16: GsG5c0UhuhXUPj4XlY8G1kcjKioiFrqI | P16: application/json | Q16: 20006IU77902 | R16: send-funds.initiate
A17: 16 | B17: Y | C17: Y | D17: TS-EB-SB-PRODUCTS-0114 | E17: TS-EB-SB-PRODUCTS-0114: Account Authentication via Access Token v1.0_Generate Account Access Token API_Validate POST Request using Valid values in Scope | F17: Send POST Request using Valid Scope value with valid client-credentials. | G17: Successful Status 200 OK - Valid scope indicated in Request Body Parameters contains [send-funds.initiate, receive-funds.generate, manage-funds.balance] (subscribed capabilities) | H17: 200 | J17: /auth/token/v1/generate | K17: application/json | L17: 1VjIqTcMCJ8tIv8bMpv9l9x01ebYQd88 | M17: cnfKqb1Q53rmlS8HifRZf7zvtGZOSlUQ | N17: 104234abc4 | O17: GsG5c0UhuhXUPj4XlY8G1kcjKioiFrqI | P17: application/json | Q17: 200061777902 | R17: send-funds.initiate
A18: 17 | B18: Y | C18: Y | D18: TS-EB-SB-PRODUCTS-0115 | E18: TS-EB-SB-PRODUCTS-0115: Account Authentication via Access Token v1.0_Generate Account Access Token API_Validate POST Request using Invalid values in Scope | F18: Send POST Request using Invalid Scope value with valid client-credentials. | G18: Failed / Rejected Request 400 Bad Request -invalid_scope with clear errorDescription. contains unknown or disallowed values [send-funds.initiate, , manage-funds.balance] (not subscribed capabilities) | H18: 400 | I18: The scope provided is invalid or not recognized | J18: /auth/token/v1/generate | K18: application/json | L18: 1VjIqTcMCJ8tIv8bMpv9l9x01ebYQd88 | M18: cnfKqb1Q53rmlS8HifRZf7zvtGZOSlUQ | N18: 104234abc4 | O18: GsG5c0UhuhXUPj4XlY8G1kcjKioiFrqI | P18: application/json | Q18: 200061777902 | R18: send-funds.invalid
A19: 18 | B19: N | C19: N | D19: TS-EB-SB-PRODUCTS-0001 | E19: TS-EB-SB-PRODUCTS-0001: Account Authentication via Access Token v1.0_Generate Account Access Token API_Verify Successful API call with Valid Account Access Token | F19: Send POST Request using Valid Account Access Token | G19: Successful Status 200 OK API request successfully processed Ownership and consent verified Token validation executes in p99 latency < 30 ms. | H19: 200 | J19: /auth/token/v1/generate | K19: application/json | L19: 1VjIqTcMCJ8tIv8bMpv9l9x01ebYQd88 | M19: cnfKqb1Q53rmlS8HifRZf7zvtGZOSlUQ | N19: 1042346954 | O19: GsG5c0UhuhXUPj4XlY8G1kcjKioiFrqI | P19: application/json | Q19: 200061777902 | R19: send-funds.initiate
A20: 19 | B20: N | C20: N | D20: TS-EB-SB-PRODUCTS-0002 | E20: TS-EB-SB-PRODUCTS-0002: Account Authentication via Access Token v1.0_Generate Account Access Token API_Verify API Call using Expired Account Access Token | F20: Send POST Request using Expired Account Access Token | G20: Failed/Rejected Status 401 Unauthorized - clear error message. -Token validation executes in p99 latency < 30 ms. | H20: 401 | J20: /auth/token/v1/generate | K20: application/json | L20: 1VjIqTcMCJ8tIv8bMpv9l9x01ebYQd88 | M20: cnfKqb1Q53rmlS8HifRZf7zvtGZOSlUQ | N20: 1042346954 | O20: GsG5c0UhuhXUPj4XlY8G1kcjKioiFrqI | P20: application/json | Q20: 200061777902 | R20: send-funds.initiate
A21: 20 | B21: N | C21: N | D21: TS-EB-SB-PRODUCTS-0003 | E21: TS-EB-SB-PRODUCTS-0003: Account Authentication via Access Token v1.0_Generate Account Access Token API_Verify API Call using Exceeding / FewerAccount Access Token | F21: Send POST Request using Exceeding/Fewer Account Access Token | G21: Failed/Rejected Status 401 Unauthorized - clear error message. - Token validation executes in p99 latency < 30 ms. | H21: 401 | J21: /auth/token/v1/generate | K21: application/json | L21: 1VjIqTcMCJ8tIv8bMpv9l9x01ebYQd88 | M21: cnfKqb1Q53rmlS8HifRZf7zvtGZOSlUQ | N21: 1042346954 | O21: GsG5c0UhuhXUPj4XlY8G1kcjKioiFrqI | P21: application/json | Q21: 200061777902 | R21: send-funds.initiate
A22: 21 | B22: N | C22: N | D22: TS-EB-SB-PRODUCTS-0004 | E22: TS-EB-SB-PRODUCTS-0004: Account Authentication via Access Token v1.0_Generate Account Access Token API_Verify API Call without Valid Account Access Token | F22: Send POST Request without VALID Account Access Token | G22: Failed/Rejected Status 401 Unauthorized - clear error message. - Token validation executes in p99 latency < 30 ms. | H22: 401 | J22: /auth/token/v1/generate | K22: application/json | L22: 1VjIqTcMCJ8tIv8bMpv9l9x01ebYQd88 | M22: cnfKqb1Q53rmlS8HifRZf7zvtGZOSlUQ | N22: 1042346954 | O22: GsG5c0UhuhXUPj4XlY8G1kcjKioiFrqI | P22: application/json | Q22: 200061777902 | R22: send-funds.initiate
A23: 22 | B23: N | C23: N | D23: TS-EB-SB-PRODUCTS-0005 | E23: TS-EB-SB-PRODUCTS-0005: Account Authentication via Access Token v1.0_Generate Account Access Token API_Verify API Call using malformed Account Access Token | F23: Send POST Request using Malformed Account Access Token | G23: Failed/Rejected Status 401 Unauthorized - clear error message. - Token validation executes in p99 latency < 30 ms. | H23: 401 | J23: /auth/token/v1/generate | K23: application/json | L23: 1VjIqTcMCJ8tIv8bMpv9l9x01ebYQd88 | M23: cnfKqb1Q53rmlS8HifRZf7zvtGZOSlUQ | N23: 1042346954 | O23: GsG5c0UhuhXUPj4XlY8G1kcjKioiFrqI | P23: application/json | Q23: 200061777902 | R23: send-funds.initiate
A24: 23 | B24: N | C24: N | D24: TS-EB-SB-PRODUCTS-0006 | E24: TS-EB-SB-PRODUCTS-0006: Account Authentication via Access Token v1.0_Generate Account Access Token API_Verify API Call using Token used with different client credentials | F24: Send POST Request using Valid Account Access Token but different client credentials | G24: Failed/Rejected Status 401 Unauthorized - clear error message. Error: Token does not match client credentials - Token validation executes in p99 latency < 30 ms. | H24: 401 | J24: /auth/token/v1/generate | K24: application/json | L24: 1VjIqTcMCJ8tIv8bMpv9l9x01ebYQd89 | M24: cnfKqb1Q53rmlS8HifRZf7zvtGZOSlUI | N24: 1042346954 | O24: GsG5c0UhuhXUPj4XlY8G1kcjKioiFrqI | P24: application/json | Q24: 200061777902 | R24: send-funds.initiate
A25: 24 | B25: N | C25: N | D25: TS-EB-SB-PRODUCTS-0007 | E25: TS-EB-SB-PRODUCTS-0007: Account Authentication via Access Token v1.0_Generate Account Access Token API_Token used with different Partner-ID | F25: Send POST Request using Valid Account Access Token but different Partner-ID | G25: Failed/Rejected Status 401 Unauthorized - clear error message. Enforcement failure due to Partner-ID mismatch - Token validation executes in p99 latency < 30 ms. | H25: 401 | J25: /auth/token/v1/generate | K25: application/json | L25: 1VjIqTcMCJ8tIv8bMpv9l9x01ebYQd88 | M25: cnfKqb1Q53rmlS8HifRZf7zvtGZOSlUQ | N25: 1042346954 | O25: GsG5c0UhuhXUPj4XlY8G1kcjKioiFrqI | P25: application/json | Q25: 200061777902 | R25: send-funds.initiate
A26: 25 | B26: N | C26: N | D26: TS-EB-SB-PRODUCTS-0104 | E26: TS-EB-SB-PRODUCTS-0104: Account Authentication via Access Token v1.0_Generate Account Access Token API_Verify send request from an IP not whitelisted for the application. | F26: Send POST Request using Not Whitelisted IP | G26: Failed Request 403 (Forbidden) No token generated | H26: 403 | J26: /auth/token/v1/generate | K26: application/json | L26: 1VjIqTcMCJ8tIv8bMpv9l9x01ebYQd88 | M26: cnfKqb1Q53rmlS8HifRZf7zvtGZOSlUQ | N26: 1042346954 | O26: GsG5c0UhuhXUPj4XlY8G1kcjKioiFrqI | P26: application/json | Q26: 200061777902 | R26: send-funds.initiate
A27: 26 | B27: N | C27: N | D27: TS-EB-SB-PRODUCTS-0106 | E27: TS-EB-SB-PRODUCTS-0106: Account Authentication via Access Token v1.0_Generate Account Access Token API_Verify status in Database of successful Client Owned Account Authentication | F27: Send POST Request using valid ACTIVE Client Owned Account with valid client-credentials. Validate DB | G27: Status in DB is COMPLETED | H27: 200 | J27: /auth/token/v1/generate | K27: application/json | L27: 1VjIqTcMCJ8tIv8bMpv9l9x01ebYQd88 | M27: cnfKqb1Q53rmlS8HifRZf7zvtGZOSlUQ | N27: 1042346954 | O27: GsG5c0UhuhXUPj4XlY8G1kcjKioiFrqI | P27: application/json | Q27: 200061777902 | R27: send-funds.initiate

Sheet SBBankList
A1: # | B1: ExecutionFlag | C1: CORE | D1: TC_ID | E1: Description | F1: StepAction | G1: ExpectedResult | H1: ExpectedStatus | I1: ExpectedResponseDescription | J1: IN_EndPoint | K1: IN_ParamChannel | L1: IN_HeadPartnerID | M1: IN_HeadAPIKey | N1: IN_HeadCorrelationID | O1: OUT_RequestHeaders | P1: OUT_RequestBody | Q1: OUT_ResponseHeaders | R1: OUT_ResponseBody
A2: 1 | B2: =C2 -> Y | C2: Y | D2: TS-EB-SB-PRODUCTS-0088 | E2: TS-EB-SB-PRODUCTS-0088: Send Funds via Local Fund Transfer v1.0 _Get Supported Banks and Wallets API_Verify successful GET request of Get Supported Banks and Wallets API | F2: Send GET Request of Get Supported Banks and Wallets API | G2: Status HTTP 200 OK Response Body: Complete and accurate list of Supported Receiving Financial Institutions (banks and e‑wallets) available for disbursements under the Send Funds via Local Fund Transfer product. { "data": [ { "bankName": "Alipay / Lazada Wallet", "pesonet": { "status": false, "brstn": "" }, "instapay": { "status": true, "brstn": "7021" }, "enable": true }, { "bankName": "Zybi Tech Inc. / JuanCash", "pesonet": { "status": true, "brstn": "18080012" }, "instapay": { "status": true, "brstn": "7012" }, "enable": true } ] } Institutioin Entries: Institution name, enablement flag, and supported settlement rails with corresponding Bank Identification Codes (BICs) where applicable. | H2: 200 | J2: /send-funds/localft/v1/list/institutions | L2: 104234abc4 | M2: GsG5c0UhuhXUPj4XlY8G1kcjKioiFrqI | N2: application/json
A3: 2 | B3: =C3 -> Y | C3: Y | D3: TS-EB-SB-PRODUCTS-0089 | E3: TS-EB-SB-PRODUCTS-0089: Send Funds via Local Fund Transfer v1.0 _Get Supported Banks and Wallets API_Verify when Optional field "Transfer Network" (channel) is not provided to filter Financial Institutions | F3: Send GET Request of Get Supported Banks and Wallets API when channel is empty | G3: When list channel parameter is not provided, the API returns institutions across all supported transfer networks channel: Intrabank, Instapay, PESONet) Sample Response Body: "data": [ { "bankName": "Alipay / Lazada Wallet", "pesonet": { "status": false, "brstn": "" }, "instapay": { "status": true, "brstn": "7021" }, "enable": true }, { "bankName": "Zybi Tech Inc. / JuanCash", "pesonet": { "status": true, "brstn": "18080012" }, "instapay": { "status": true, "brstn": "7012" }, "enable": true } ] } | H3: 200 | J3: /send-funds/localft/v1/list/institutions | L3: 104234abc4 | M3: GsG5c0UhuhXUPj4XlY8G1kcjKioiFrqI | N3: application/json
A4: 3 | B4: =C4 -> Y | C4: Y | D4: TS-EB-SB-PRODUCTS-0090 | E4: TS-EB-SB-PRODUCTS-0090: Send Funds via Local Fund Transfer v1.0 _Get Supported Banks and Wallets API_Verify when the “Transfer Network” (channel) is set to Instapay, the API returns only Financial Institutions that support Instapay transfers | F4: Send GET Request of Get Supported Banks and Wallets API when channel = InstaPay | G4: When list channel parameter is provided, the API returns only Financial institutions that support the Intrabank Transfer Network channel: Instapay "data": [ { "bankName": "Alipay / Lazada Wallet", "pesonet": { "status": false, "brstn": "" }, "instapay": { "status": true, "brstn": "7021" }, "enable": true }, { "bankName": "Zybi Tech Inc. / JuanCash", "pesonet": { "status": true, "brstn": "18080012" }, "instapay": { "status": true, "brstn": "7012" }, "enable": true } ] } | H4: 200 | J4: ="/send-funds/localft/v1/list/institutions?channel="&K4 -> /send-funds/localft/v1/list/institutions?channel=Instapay | K4: Instapay | L4: 104234abc4 | M4: GsG5c0UhuhXUPj4XlY8G1kcjKioiFrqI | N4: application/json
A5: 4 | B5: =C5 -> Y | C5: Y | D5: TS-EB-SB-PRODUCTS-0091 | E5: TS-EB-SB-PRODUCTS-0091: Send Funds via Local Fund Transfer v1.0 _Get Supported Banks and Wallets API_Verify when the “Transfer Network” (channel) is set to PESONet, the API returns only Financial Institutions that support PESONet transfers | F5: Send GET Request of Get Supported Banks and Wallets API when channel = PESONet | G5: When list channel parameter is provided, the API returns only Financial institutions that support the PESONet Transfer Network channel: PESONet "data": [ { "bankName": "Zybi Tech Inc. / JuanCash", "pesonet": { "status": true, "brstn": "18080012" }, "instapay": { "status": true, "brstn": "7012" }, "enable": true } ] } | H5: 200 | J5: ="/send-funds/localft/v1/list/institutions?channel="&K5 -> /send-funds/localft/v1/list/institutions?channel=PESONET | K5: PESONET | L5: 104234abc4 | M5: GsG5c0UhuhXUPj4XlY8G1kcjKioiFrqI | N5: application/json
A6: 5 | B6: =C6 -> Y | C6: Y | D6: TS-EB-SB-PRODUCTS-0092 | E6: TS-EB-SB-PRODUCTS-0092: Send Funds via Local Fund Transfer v1.0 _Get Supported Banks and Wallets API_Verify when the “Transfer Network” (channel) is set to specific and API returns only Financial Institutions that support both transfers | F6: Send GET Request of Get Supported Banks and Wallets API when channel is set to specific and API returns only Financial Institutions that support both transfers | G6: The API should display both enable for both transfers (Ex: pesonet and instapay) Sample Response Body: "data": [ { "bankName": "Zybi Tech Inc. / JuanCash", "pesonet": { "status": true, "brstn": "18080012" }, "instapay": { "status": true, "brstn": "7012" }, "enable": true } ] } | H6: 200 | J6: /send-funds/localft/v1/list/institutions | L6: 104234abc4 | M6: GsG5c0UhuhXUPj4XlY8G1kcjKioiFrqI | N6: application/json
A7: 6 | B7: =C7 -> Y | C7: Y | D7: TS-EB-SB-PRODUCTS-0093 | E7: TS-EB-SB-PRODUCTS-0093: Send Funds via Local Fund Transfer v1.0 _Get Supported Banks and Wallets API_Verify failed GET request when an unsupported channel value is provided | F7: Send GET Request of Get Supported Banks and Wallets API when channel is set to unsupported channel | G7: HTTP 400 Bad Request Clear error message indicating invalid or unsupported channel value (e.g., channel=ABC) (responseDescription) | H7: 400 | I7: Invalid Channel. The Channel provided is invalid. | J7: ="/send-funds/localft/v1/list/institutions?channel="&K7 -> /send-funds/localft/v1/list/institutions?channel=Test | K7: Test | L7: 104234abc4 | M7: GsG5c0UhuhXUPj4XlY8G1kcjKioiFrqI | N7: application/json
A8: 7 | B8: =C8 -> Y | C8: Y | D8: TS-EB-SB-PRODUCTS-0094 | E8: TS-EB-SB-PRODUCTS-0094: Send Funds via Local Fund Transfer v1.0_Get Supported Banks and Wallets API_Verify failed GET request when api-key is null/missing | F8: Send GET Request of Get Supported Banks and Wallets API but api k-key is not provided/missing | G8: HTTP 401 Unauthorized Clear authentication error message (responseDescription) | H8: 401 | I8: Invalid API key. The API key provided was not found. | J8: /send-funds/localft/v1/list/institutions | L8: 104234abc4 | N8: application/json
A9: 8 | B9: =C9 -> Y | C9: Y | D9: TS-EB-SB-PRODUCTS-0095 | E9: TS-EB-SB-PRODUCTS-0095: Send Funds via Local Fund Transfer v1.0_Get Supported Banks and Wallets API_Verify failed GET request when partnerID is null/missing | F9: Send GET Request of Get Supported Banks and Wallets API but partnerId is not provided/missing | G9: HTTP 401 Unauthorized Clear authentication error message (responseDescription) | H9: 401 | I9: The partner ID provided is invalid, not recognized, or not registered in Client Hub. | J9: /send-funds/localft/v1/list/institutions | M9: GsG5c0UhuhXUPj4XlY8G1kcjKioiFrqI | N9: application/json
A10: 9 | B10: =C10 -> Y | C10: Y | D10: TS-EB-SB-PRODUCTS-0096 | E10: TS-EB-SB-PRODUCTS-0096: Send Funds via Local Fund Transfer v1.0_Get Supported Banks and Wallets API_Verify failed GET request when api-key is incorrect | F10: Send GET Request of Get Supported Banks and Wallets API but api-key is incorrect or not existing | G10: HTTP 401 Unauthorized Clear authentication error message (responseDescription) | H10: 401 | I10: Invalid API key. The API key provided was not found. | J10: /send-funds/localft/v1/list/institutions | L10: 104234abc4 | M10: GsG5c0UhuhXUPj4XliKG1kcjKioiT5qI | N10: application/json
A11: 10 | B11: =C11 -> Y | C11: Y | D11: TS-EB-SB-PRODUCTS-0097 | E11: TS-EB-SB-PRODUCTS-0097: Send Funds via Local Fund Transfer v1.0_Get Supported Banks and Wallets API_Verify failed GET request when partnerid is incorrect | F11: Send GET Request of Get Supported Banks and Wallets API but partnerId is incorrect or not existing | G11: HTTP 401 Unauthorized Clear authentication error message (responseDescription) | H11: 401 | I11: The partner ID provided is invalid, not recognized, or not registered in Client Hub. | J11: /send-funds/localft/v1/list/institutions | L11: 1042346054 | M11: GsG5c0UhuhXUPj4XlY8G1kcjKioiFrqI | N11: application/json
A12: 12 | B12: =C12 -> Y | C12: Y | D12: TS-EB-SB-PRODUCTS-0099 | E12: TS-EB-SB-PRODUCTS-0099: Send Funds via Local Fund Transfer v1.0_Get Supported Banks and Wallets API_Verify disabled institutions are clearly indicated and not misrepresented as available | F12: Send GET Request of Get Supported Banks and Wallets API | G12: Disabled institutions are marked correctly They are not shown as valid disbursement destinations | H12: 200 | J12: /send-funds/localft/v1/list/institutions | L12: 104234abc4 | M12: GsG5c0UhuhXUPj4XlY8G1kcjKioiFrqI | N12: application/json
A13: 13 | B13: =C13 -> Y | C13: Y | D13: TS-EB-SB-PRODUCTS-0100 | E13: TS-EB-SB-PRODUCTS-0100: Send Funds via Local Fund Transfer v1.0_Get Supported Banks and Wallets API_Verify response processsing time of successful GET request of Get Supported Banks and Wallets API | F13: Send Successful GET Request of Get Supported Banks and Wallets API. Check processing time. | G13: 200 OK response within ≤ 1 second (1000 ms) for 95% of calls. | H13: 200 | J13: /send-funds/localft/v1/list/institutions | L13: 104234abc4 | M13: GsG5c0UhuhXUPj4XlY8G1kcjKioiFrqI | N13: application/json
A14: 14 | B14: =C14 -> Y | C14: Y | D14: TS-EB-SB-PRODUCTS-0101_1 | E14: TS-EB-SB-PRODUCTS-0101_1: Send Funds via Local Fund Transfer v1.0_Get Supported Banks and Wallets API_Verify response processsing time of failed GET request of Get Supported Banks and Wallets API | F14: Send GET Request of Get Supported Banks and Wallets API when channel is set to unsupported channel | G14: 400 status with descriptive error message within ≤ 1 second | H14: 400 | I14: Invalid Channel. The Channel provided is invalid. | J14: ="/send-funds/localft/v1/list/institutions?channel="&K14 -> /send-funds/localft/v1/list/institutions?channel=Test | K14: Test | L14: 104234abc4 | M14: GsG5c0UhuhXUPj4XlY8G1kcjKioiFrqI | N14: application/json
A15: 15 | B15: =C15 -> Y | C15: Y | D15: TS-EB-SB-PRODUCTS-0101_2 | E15: TS-EB-SB-PRODUCTS-0101_2: Send Funds via Local Fund Transfer v1.0_Get Supported Banks and Wallets API_Verify response processsing time of failed GET request of Get Supported Banks and Wallets API | F15: Send GET Request of Get Supported Banks and Wallets API but api k-key is not provided/missing | G15: 401 status with descriptive error message within ≤ 1 second | H15: 401 | I15: Invalid API key. The API key provided was not found. | J15: /send-funds/localft/v1/list/institutions | L15: 104234abc4 | N15: application/json
A16: 16 | B16: =C16 -> Y | C16: Y | D16: TS-EB-SB-PRODUCTS-0101_3 | E16: TS-EB-SB-PRODUCTS-0101_3: Send Funds via Local Fund Transfer v1.0_Get Supported Banks and Wallets API_Verify response processsing time of failed GET request of Get Supported Banks and Wallets API | F16: Send GET Request of Get Supported Banks and Wallets API but partnerId is not provided/missing | G16: 401 status with descriptive error message within ≤ 1 second | H16: 401 | I16: The partner ID provided is invalid, not recognized, or not registered in Client Hub. | J16: /send-funds/localft/v1/list/institutions | M16: GsG5c0UhuhXUPj4XlY8G1kcjKioiFrqI | N16: application/json
A17: 17 | B17: =C17 -> Y | C17: Y | D17: TS-EB-SB-PRODUCTS-0101_4 | E17: TS-EB-SB-PRODUCTS-0101_4: Send Funds via Local Fund Transfer v1.0_Get Supported Banks and Wallets API_Verify response processsing time of failed GET request of Get Supported Banks and Wallets API | F17: Send GET Request of Get Supported Banks and Wallets API but api-key is incorrect or not existing | G17: 401 status with descriptive error message within ≤ 1 second | H17: 401 | I17: Invalid API key. The API key provided was not found. | J17: /send-funds/localft/v1/list/institutions | L17: 104234abc4 | M17: GsG5c0UhuhXUPj4XliKG1kcjKioiT5qI | N17: application/json
A18: 18 | B18: =C18 -> Y | C18: Y | D18: TS-EB-SB-PRODUCTS-0101_5 | E18: TS-EB-SB-PRODUCTS-0101_5: Send Funds via Local Fund Transfer v1.0_Get Supported Banks and Wallets API_Verify response processsing time of failed GET request of Get Supported Banks and Wallets API | F18: Send GET Request of Get Supported Banks and Wallets API but partnerId is incorrect or not existing | G18: 401 status with descriptive error message within ≤ 1 second | H18: 401 | I18: The partner ID provided is invalid, not recognized, or not registered in Client Hub. | J18: /send-funds/localft/v1/list/institutions | L18: 1042346054 | M18: GsG5c0UhuhXUPj4XlY8G1kcjKioiFrqI | N18: application/json
A19: 19 | B19: =C19 -> N | C19: N | D19: TS-EB-SB-PRODUCTS-0098 | E19: TS-EB-SB-PRODUCTS-0098: Send Funds via Local Fund Transfer v1.0_Get Supported Banks and Wallets API_Verify failed GET request when application is not subscribed to the API product | F19: Send GET Request of Get Supported Banks and Wallets API but application is not subscribed to API Product | G19: HTTP 403 Forbidden Clear subscription or authorization error message (responseDescription) | H19: 403 | J19: /send-funds/localft/v1/list/institutions | L19: 1042346954 | M19: GsG5c0UhuhXUPj4XlY8G1kcjKioiFrqI | N19: application/json

Sheet SBCheckStatus
A1: # | B1: ExecutionFlag | C1: CORE | D1: TC_ID | E1: Description | F1: StepAction | G1: ExpectedResult | H1: ExpectedStatus | I1: ExpectedResponseDescription | J1: IN_EndPoint | K1: IN_ParamAPITxnID | L1: IN_ParamAPITxnRef | M1: IN_ParamIdempotencyKey | N1: IN_HeadPartnerID | O1: IN_HeadAPIKey | P1: IN_HeadContentType | Q1: OUT_RequestHeaders | R1: OUT_RequestBody | S1: OUT_ResponseHeaders | T1: OUT_ResponseBody
A2: 1 | B2: =C2 -> Y | C2: Y | D2: TS-EB-PRODUCTS-0205 | E2: TS-EB-PRODUCTS-0205: Send Funds via Local Fund Transfer v1.0 _Check Local Funds Transfer Details and Status API_Verify failed GET request of Local Fund Transfer (Transaction Details) upon providing Exceeding to 23 digits of API-Txn-Ref via Intrabank | F2: Send GET Request of Check Local Fund Transfer Details and Status API using exceeding to 23-digits Transaction ID (API-Txn-Ref) via Intrabank | G2: The API returns an error message as the transaction details of provided transaction reference is persistent 23-digit transaction reference Status: 400 Bad RequeststatusDescription | H2: 400 | I2: Query parameter apiTxnRef must be a 23-character alphanumeric string. | J2: /send-funds/localft/v1/status | L2: 111111854000000000000628 | N2: 104234abc4 | O2: GsG5c0UhuhXUPj4XlY8G1kcjKioiFrqI | P2: application/json
A3: 2 | B3: =C3 -> Y | C3: Y | D3: TS-EB-PRODUCTS-0206 | E3: TS-EB-PRODUCTS-0206: Send Funds via Local Fund Transfer v1.0 _Check Local Funds Transfer Details and Status API_Verify failed GET request of Local Fund Transfer (Transaction Details) upon providing fewer than 23 digits of API-Txn-Ref via Intrabank | F3: Send GET Request of Check Local Fund Transfer Details and Status API using fewer than 23-digits Transaction ID (API-Txn-Ref) via Intrabank | G3: The API returns an error message as the transaction details of provided transaction reference is persistent 23-digit transaction reference Status: 400 Bad RequeststatusDescription | H3: 400 | I3: Query parameter apiTxnRef must be a 23-character alphanumeric string. | J3: /send-funds/localft/v1/status | L3: 1111118540000000000006 | N3: 104234abc4 | O3: GsG5c0UhuhXUPj4XlY8G1kcjKioiFrqI | P3: application/json
A4: 3 | B4: =C4 -> Y | C4: Y | D4: TS-EB-PRODUCTS-0286 | E4: TS-EB-PRODUCTS-0286: Send Funds via Local Fund Transfer v1.0 _Check Local Funds Transfer Details and Status API_Verify failed GET request of Local Fund Transfer (Transaction Details) upon providing Exceeding to 23 digits of API-Txn-Ref via InstaPay | F4: Send GET Request of Check Local Fund Transfer Details and Status API using exceeding to 23-digits Transaction Ref (API-Txn-Ref) via InstaPay | G4: The API returns an error message as the transaction details of provided transaction reference is persistent 23-digit transaction reference Status: 400 Bad Request statusDescription | H4: 400 | I4: Query parameter apiTxnRef must be a 23-character alphanumeric string. | J4: /send-funds/localft/v1/status | L4: 111111773000000000000625 | N4: 104234abc4 | O4: GsG5c0UhuhXUPj4XlY8G1kcjKioiFrqI | P4: application/json
A5: 4 | B5: =C5 -> Y | C5: Y | D5: TS-EB-PRODUCTS-0287 | E5: TS-EB-PRODUCTS-0287: Send Funds via Local Fund Transfer v1.0 _Check Local Funds Transfer Details and Status API_Verify failed GET request of Local Fund Transfer (Transaction Details) upon providing Exceeding to 23 digits of API-Txn-Ref via PESONet | F5: Send GET Request of Check Local Fund Transfer Details and Status API using exceeding to 23-digits Transaction ID (API-Txn-Ref) via PESONet | G5: The API returns an error message as the transaction details of provided transaction reference is persistent 23-digit transaction reference Status: 400 Bad Request statusDescription | H5: 400 | I5: Query parameter apiTxnRef must be a 23-character alphanumeric string. | J5: /send-funds/localft/v1/status | L5: 1111117730000000000006 | N5: 104234abc4 | O5: GsG5c0UhuhXUPj4XlY8G1kcjKioiFrqI | P5: application/json
A6: 5 | B6: =C6 -> Y | C6: Y | D6: TS-EB-PRODUCTS-0288 | E6: TS-EB-PRODUCTS-0288: Send Funds via Local Fund Transfer v1.0 _Check Local Funds Transfer Details and Status API_Verify failed GET request of Local Fund Transfer (Transaction Details) upon providing fewer than 23 digits of API-Txn-Ref via InstaPay | F6: Send GET Request of Check Local Fund Transfer Details and Status API using fewer than 23-digits Transaction Ref (API-Txn-Ref) via InstaPay | G6: The API returns an error message as the transaction details of provided transaction reference is persistent 23-digit transaction reference Status: 400 Bad Request statusDescription | H6: 400 | I6: Query parameter apiTxnRef must be a 23-character alphanumeric string. | J6: /send-funds/localft/v1/status | L6: 1111117750000000000006289 | N6: 104234abc4 | O6: GsG5c0UhuhXUPj4XlY8G1kcjKioiFrqI | P6: application/json
A7: 6 | B7: =C7 -> Y | C7: Y | D7: TS-EB-PRODUCTS-0289 | E7: TS-EB-PRODUCTS-0289: Send Funds via Local Fund Transfer v1.0 _Check Local Funds Transfer Details and Status API_Verify failed GET request of Local Fund Transfer (Transaction Details) upon providing fewer than 23 digits of API-Txn-Ref via PESONet | F7: Send GET Request of Check Local Fund Transfer Details and Status API using fewer than 23-digits Transaction Ref (API-Txn-Ref) via PESONet | G7: The API returns an error message as the transaction details of provided transaction reference is persistent 23-digit transaction reference Status: 400 Bad Request statusDescription | H7: 400 | I7: Query parameter apiTxnRef must be a 23-character alphanumeric string. | J7: /send-funds/localft/v1/status | L7: 111111775000000000000 | N7: 104234abc4 | O7: GsG5c0UhuhXUPj4XlY8G1kcjKioiFrqI | P7: application/json
A8: 7 | B8: =C8 -> Y | C8: Y | D8: TS-EB-PRODUCTS-0187 | E8: TS-EB-PRODUCTS-0187: Send Funds via Local Fund Transfer v1.0 _Check Local Funds Transfer Details and Status API_Verify successful GET request of Check Local Fund Transfer Details and Status API for Intrabank | F8: Send GET Request of Check Local Fund Transfer Details and Status API | G8: Status HTTP 200 OK [within ≤ 1 second (1000 ms)] Response Body: apiTxnIdapiTxnRef ewbCoreReferencestatus = always "RECEIVED"responseCoderesponseDescriptioncreatedTimestampupdatedTimestamp | H8: 200 | J8: /send-funds/localft/v1/status | L8: 11111185400000000000062 | N8: 104234abc4 | O8: GsG5c0UhuhXUPj4XlY8G1kcjKioiFrqI | P8: application/json
A9: 8 | B9: =C9 -> Y | C9: Y | D9: TS-EB-PRODUCTS-0192 | E9: TS-EB-PRODUCTS-0192: Send Funds via Local Fund Transfer v1.0 _Check Local Funds Transfer Details and Status API_VVerify failed GET request of Check Local Fund Transfer Details and Status API due to invalid partner-id parameters via Intrabank transfer | F9: Send GET Request of Check Local Fund Transfer Details and Status API using invalid partner-id parameter for Intrabank Transfer | G9: responseCode (Status HTTP 401 Unauthorized[within ≤ 1 second (1000 ms)]}and responseDescription - must be included in API Portal Database | H9: 401 | I9: The partner ID provided is invalid, not recognized, or not registered in Client Hub. | J9: /send-funds/localft/v1/status | L9: 11111185400000000000062 | N9: 1042346950 | O9: GsG5c0UhuhXUPj4XlY8G1kcjKioiFrqI | P9: application/json
A10: 9 | B10: =C10 -> Y | C10: Y | D10: TS-EB-PRODUCTS-0195_2 | E10: TS-EB-PRODUCTS-0195_2: Send Funds via Local Fund Transfer v1.0 _Check Local Funds Transfer Details and Status API_Verify Check Local Fund Transfer Details and Status API when transaction is not yet in its final status (COMPLETED/FAILED) | F10: Send GET Request of Check Local Fund Transfer Details and Status API when created transaction is not yet in final status (COMPLETE/FAILED) | G10: API should trigger a status check with the core/downstream systems when invoked | H10: 200 | J10: /send-funds/localft/v1/status | K10: 223 | N10: 104234abc4 | O10: GsG5c0UhuhXUPj4XlY8G1kcjKioiFrqI | P10: application/json
A11: 10 | B11: =C11 -> Y | C11: Y | D11: TS-EB-PRODUCTS-0195_3 | E11: TS-EB-PRODUCTS-0195_3: Send Funds via Local Fund Transfer v1.0 _Check Local Funds Transfer Details and Status API_Verify Check Local Fund Transfer Details and Status API when transaction is not yet in its final status (COMPLETED/FAILED) | F11: Send GET Request of Check Local Fund Transfer Details and Status API when created transaction is not yet in final status (COMPLETE/FAILED) | G11: API should trigger a status check with the core/downstream systems when invoked | H11: 200 | J11: /send-funds/localft/v1/status | K11: 113 | N11: 104234abc4 | O11: GsG5c0UhuhXUPj4XlY8G1kcjKioiFrqI | P11: application/json
A12: 11 | B12: =C12 -> Y | C12: Y | D12: TS-EB-PRODUCTS-0196 | E12: TS-EB-PRODUCTS-0196: Send Funds via Local Fund Transfer v1.0 _Check Local Funds Transfer Details and Status API_Verify successful retrieval of local funds transfer details using a valid idempotency key Intrabank | F12: Send GET Request of Check Local Fund Transfer Details and Status API using valid idempotency-key via Intrabank | G12: API returns 200 OK statusFull transaction details and latest status are returned Response Body: apiTxnIdapiTxnRef ewbCoreReferencestatus = always "RECEIVED"responseCoderesponseDescriptioncreatedTimestampupdatedTimestamp | H12: 200 | J12: /send-funds/localft/v1/status | M12: 3300000000000 | N12: 104234abc4 | O12: GsG5c0UhuhXUPj4XlY8G1kcjKioiFrqI | P12: application/json
A13: 12 | B13: =C13 -> Y | C13: Y | D13: TS-EB-PRODUCTS-0197 | E13: TS-EB-PRODUCTS-0197: Send Funds via Local Fund Transfer v1.0 _Check Local Funds Transfer Details and Status API_Verify failed retrieval of local funds transfer details using a non‑existing idempotency key via Intrabank | F13: Send GET Request of Check Local Fund Transfer Details and Status API using not existing idempotency-key via Intabank | G13: Error response is returned 404 Not Found / 400 Bad RequestTransaction details are not found responseCoderesponseDescription | H13: 400 | I13: Transaction not found for the provided idempotencyKey | J13: /send-funds/localft/v1/status | M13: 5500000000000 | N13: 104234abc4 | O13: GsG5c0UhuhXUPj4XlY8G1kcjKioiFrqI | P13: application/json
A14: 13 | B14: =C14 -> Y | C14: Y | D14: TS-EB-PRODUCTS-0198 | E14: TS-EB-PRODUCTS-0198: Send Funds via Local Fund Transfer v1.0 _Check Local Funds Transfer Details and Status API_Verify failed retrieval of local funds transfer details using an invalid idempotency key format via Intrabank | F14: Send GET Request of Check Local Fund Transfer Details and Status API using invalid idempotency-key format via Intrabank | G14: Error response is returned 404 Not Found / 400 Bad RequestTransaction details are not found responseCoderesponseDescription | H14: 400 | I14: Transaction not found for the provided idempotencyKey | J14: /send-funds/localft/v1/status | M14: 5500000000000 | N14: 104234abc4 | O14: GsG5c0UhuhXUPj4XlY8G1kcjKioiFrqI | P14: application/json
A15: 14 | B15: =C15 -> Y | C15: Y | D15: TS-EB-PRODUCTS-0200 | E15: TS-EB-PRODUCTS-0200: Send Funds via Local Fund Transfer v1.0 _Check Local Funds Transfer Details and Status API_Verify successful GET request of Local Fund Transfer (Transaction Details) upon providing Valid API-Txn-ID via Intrabank | F15: Send GET Request of Check Local Fund Transfer Details and Status API using Valid Transaction ID (API-Txn-ID) via Intrabank | G15: Status HTTP 200 OK [within ≤ 1 second (1000 ms)] Response Body: apiTxnIdapiTxnRef ewbCoreReferencestatus = always "RECEIVED"responseCoderesponseDescriptioncreatedTimestampupdatedTimestamp | H15: 200 | J15: /send-funds/localft/v1/status | K15: 330 | N15: 104234abc4 | O15: GsG5c0UhuhXUPj4XlY8G1kcjKioiFrqI | P15: application/json
A16: 15 | B16: =C16 -> Y | C16: Y | D16: TS-EB-PRODUCTS-0201 | E16: TS-EB-PRODUCTS-0201: Send Funds via Local Fund Transfer v1.0 _Check Local Funds Transfer Details and Status API_Verify failed GET request of Local Fund Transfer (Transaction Details) upon providing Invalid format API-Txn-ID via Intrabank | F16: Send GET Request of Check Local Fund Transfer Details and Status API using Invalid Format Transaction ID (API-Txn-ID) via Intrabank | G16: The API returns an error message: Status 400 Bad Request / 404 Not FoundstatusDescription | H16: 400 | I16: Transaction not found for the provided apiTxnId | J16: /send-funds/localft/v1/status | K16: 550 | N16: 104234abc4 | O16: GsG5c0UhuhXUPj4XlY8G1kcjKioiFrqI | P16: application/json
A17: 16 | B17: =C17 -> Y | C17: Y | D17: TS-EB-PRODUCTS-0202 | E17: TS-EB-PRODUCTS-0202: Send Funds via Local Fund Transfer v1.0 _Check Local Funds Transfer Details and Status API_Verify failed GET request of Local Fund Transfer (Transaction Details) upon providing Not Existing API-Txn-ID via Intrabank | F17: Send GET Request of Check Local Fund Transfer Details and Status API using Not Existing Transaction ID (API-Txn-ID) via Intrabank | G17: The API returns an error message: Status 400 Bad RequeststatusDescription | H17: 400 | I17: Transaction not found for the provided apiTxnId | J17: /send-funds/localft/v1/status | K17: 550 | N17: 104234abc4 | O17: GsG5c0UhuhXUPj4XlY8G1kcjKioiFrqI | P17: application/json
A18: 17 | B18: =C18 -> Y | C18: Y | D18: TS-EB-PRODUCTS-0203 | E18: TS-EB-PRODUCTS-0203: Send Funds via Local Fund Transfer v1.0 _Check Local Funds Transfer Details and Status API_Verify successful GET request of Local Fund Transfer (Transaction Details) upon providing valid API-Txn-Ref via Intrabank | F18: Send GET Request of Check Local Fund Transfer Details and Status API using Valid Transaction ID (API-Txn-Ref) | G18: Status HTTP 200 OK [within ≤ 1 second (1000 ms)] Response Body: apiTxnIdapiTxnRef ewbCoreReferencestatus = always "RECEIVED"responseCoderesponseDescriptioncreatedTimestampupdatedTimestamp | H18: 200 | J18: /send-funds/localft/v1/status | L18: 11111185400000000000062 | N18: 104234abc4 | O18: GsG5c0UhuhXUPj4XlY8G1kcjKioiFrqI | P18: application/json
A19: 18 | B19: =C19 -> Y | C19: Y | D19: TS-EB-PRODUCTS-0204 | E19: TS-EB-PRODUCTS-0204: Send Funds via Local Fund Transfer v1.0 _Check Local Funds Transfer Details and Status API_Verify failed GET request of Local Fund Transfer (Transaction Details) upon providing Not Existing API-Txn-Ref via Intrabank | F19: Send GET Request of Check Local Fund Transfer Details and Status API using Not Existing Transaction ID (API-Txn-Ref) via Intrabank | G19: The API returns an error message as the transaction details of provided transaction reference is not existing. Status: 400 Bad RequeststatusDescription | H19: 400 | I19: Transaction not found for the provided apiTxnRef | J19: /send-funds/localft/v1/status | L19: 11111177400000000000062 | N19: 104234abc4 | O19: GsG5c0UhuhXUPj4XlY8G1kcjKioiFrqI | P19: application/json
A20: 19 | B20: =C20 -> Y | C20: Y | D20: TS-EB-PRODUCTS-0207 | E20: TS-EB-PRODUCTS-0207: Send Funds via Local Fund Transfer v1.0 _Check Local Funds Transfer Details and Status API_Verify failed GET request of Local Fund Transfer (Transaction Details) upon not providing API-Txn-Ref (Blank) via Intrabank | F20: Send GET Request of Check Local Fund Transfer Details and Status API using blank/empty Transaction ID (API-Txn-Ref) via Intrabank | G20: The API returns an error message as the transaction reference is not given but the query parameter is present. Status: 400 Bad RequeststatusDescription | H20: 400 | I20: Exactly one of idempotencyKey, apiTxnId, or apiTxnRef must be provided | J20: /send-funds/localft/v1/status | N20: 104234abc4 | O20: GsG5c0UhuhXUPj4XlY8G1kcjKioiFrqI | P20: application/json
A21: 20 | B21: =C21 -> Y | C21: Y | D21: TS-EB-PRODUCTS-0262 | E21: TS-EB-PRODUCTS-0262: Send Funds via Local Fund Transfer v1.0 _Check Local Funds Transfer Details and Status API_Verify successful GET request of Check Local Fund Transfer Details and Status API for PESONet | F21: Send GET Request of Check Local Fund Transfer Details and Status API of InstaPay transaction | G21: Status HTTP 200 OK [within ≤ 1 second (1000 ms)] Response Body: apiTxnId apiTxnRef ewbCoreReference externalRailreference (InstaPay) status = always "RECEIVED" responseCode responseDescription createdTimestamp updatedTimestamp | H21: 200 | J21: /send-funds/localft/v1/status | L21: 11111177300000000000062 | N21: 104234abc4 | O21: GsG5c0UhuhXUPj4XlY8G1kcjKioiFrqI | P21: application/json
A22: 21 | B22: =C22 -> Y | C22: Y | D22: TS-EB-PRODUCTS-0263 | E22: TS-EB-PRODUCTS-0263: Send Funds via Local Fund Transfer v1.0 _Check Local Funds Transfer Details and Status API_Verify successful GET request of Check Local Fund Transfer Details and Status API for PESONet | F22: Send GET Request of Check Local Fund Transfer Details and Status API of PESONet transaction | G22: Status HTTP 200 OK [within ≤ 1 second (1000 ms)] Response Body: apiTxnId apiTxnRef ewbCoreReference externalRailreference (PESONet) status = always "RECEIVED" responseCode responseDescription createdTimestamp updatedTimestamp | H22: 200 | J22: /send-funds/localft/v1/status | L22: 11111177500000000000062 | N22: 104234abc4 | O22: GsG5c0UhuhXUPj4XlY8G1kcjKioiFrqI | P22: application/json
A23: 22 | B23: =C23 -> Y | C23: Y | D23: TS-EB-PRODUCTS-0264 | E23: TS-EB-PRODUCTS-0264: Send Funds via Local Fund Transfer v1.0 _Check Local Funds Transfer Details and Status API_Verify failed GET request of Check Local Fund Transfer Details and Status API due to invalid partner-id parameters via InstaPay transfer | F23: Send GET Request of Check Local Fund Transfer Details and Status API using invalid partner-id parameter for InstaPay Transfer | G23: responseCode (Status HTTP 401 Unauthorized/403 Forbidden Error [within ≤ 1 second (1000 ms)]}and responseDescription - must be included in API Portal Database | H23: 401 | I23: The partner ID provided is invalid, not recognized, or not registered in Client Hub. | J23: /send-funds/localft/v1/status | L23: 11111177300000000000062 | N23: 1042346054 | O23: GsG5c0UhuhXUPj4XlY8G1kcjKioiFrqI | P23: application/json
A24: 23 | B24: =C24 -> Y | C24: Y | D24: TS-EB-PRODUCTS-0265 | E24: TS-EB-PRODUCTS-0265: Send Funds via Local Fund Transfer v1.0 _Check Local Funds Transfer Details and Status API_Verify failed GET request of Check Local Fund Transfer Details and Status API due to invalid partner-id parameters via PESONet transfer | F24: Send GET Request of Check Local Fund Transfer Details and Status API using invalid partner-id parameter for PESONet Transfer | G24: responseCode (Status HTTP 401 Unauthorized[within ≤ 1 second (1000 ms)]}and responseDescription - must be included in API Portal Database | H24: 401 | I24: The partner ID provided is invalid, not recognized, or not registered in Client Hub. | J24: /send-funds/localft/v1/status | L24: 11111177500000000000062 | N24: 1042346054 | O24: GsG5c0UhuhXUPj4XlY8G1kcjKioiFrqI | P24: application/json
A25: 24 | B25: =C25 -> Y | C25: Y | D25: TS-EB-PRODUCTS-0270 | E25: TS-EB-PRODUCTS-0270: Send Funds via Local Fund Transfer v1.0 _Check Local Funds Transfer Details and Status API_Verify successful retrieval of local funds transfer details using a valid idempotency key InstaPay | F25: Send GET Request of Check Local Fund Transfer Details and Status API using valid idempotency-key via InstaPay | G25: API returns 200 OK status Full transaction details and latest status are returned Response Body: apiTxnId apiTxnRef ewbCoreReference externalRailReference (InstaPay) status = always "RECEIVED" responseCode responseDescription createdTimestamp updatedTimestamp | H25: 200 | J25: /send-funds/localft/v1/status | M25: 1100000000000 | N25: 104234abc4 | O25: GsG5c0UhuhXUPj4XlY8G1kcjKioiFrqI | P25: application/json
A26: 25 | B26: =C26 -> Y | C26: Y | D26: TS-EB-PRODUCTS-0271 | E26: TS-EB-PRODUCTS-0271: Send Funds via Local Fund Transfer v1.0 _Check Local Funds Transfer Details and Status API_Verify successful retrieval of local funds transfer details using a valid idempotency key PESONet | F26: Send GET Request of Check Local Fund Transfer Details and Status API using valid idempotency-key via PESONet | G26: API returns 200 OK status Full transaction details and latest status are returned Response Body: apiTxnId apiTxnRef ewbCoreReference externelRailReference (PESONet) status = always "RECEIVED" responseCode responseDescription createdTimestamp updatedTimestamp | H26: 200 | J26: /send-funds/localft/v1/status | M26: 2200000000000 | N26: 104234abc4 | O26: GsG5c0UhuhXUPj4XlY8G1kcjKioiFrqI | P26: application/json
A27: 26 | B27: =C27 -> Y | C27: Y | D27: TS-EB-PRODUCTS-0272 | E27: TS-EB-PRODUCTS-0272: Send Funds via Local Fund Transfer v1.0 _Check Local Funds Transfer Details and Status API_Verify failed retrieval of local funds transfer details using a non‑existent idempotency key via InstaPay | F27: Send GET Request of Check Local Fund Transfer Details and Status API using not existing idempotency-key via InstaPay | G27: Error response is returned 404 Not Found / 400 Bad Request Transaction details are not found responseCode responseDescription | H27: 400 | I27: Transaction not found for the provided idempotencyKey | J27: /send-funds/localft/v1/status | M27: 5500000000000 | N27: 104234abc4 | O27: GsG5c0UhuhXUPj4XlY8G1kcjKioiFrqI | P27: application/json
A28: 27 | B28: =C28 -> Y | C28: Y | D28: TS-EB-PRODUCTS-0273 | E28: TS-EB-PRODUCTS-0273: Send Funds via Local Fund Transfer v1.0 _Check Local Funds Transfer Details and Status API_Verify failed retrieval of local funds transfer details using a non‑existent idempotency key via PESONet | F28: Send GET Request of Check Local Fund Transfer Details and Status API using not existing idempotency-key via PESONet | G28: Error response is returned 404 Not Found / 400 Bad Request Transaction details are not found responseCode responseDescription | H28: 400 | I28: Transaction not found for the provided idempotencyKey | J28: /send-funds/localft/v1/status | M28: 5500000000000 | N28: 104234abc4 | O28: GsG5c0UhuhXUPj4XlY8G1kcjKioiFrqI | P28: application/json
A29: 28 | B29: =C29 -> Y | C29: Y | D29: TS-EB-PRODUCTS-0274 | E29: TS-EB-PRODUCTS-0274: Send Funds via Local Fund Transfer v1.0 _Check Local Funds Transfer Details and Status API_Verify failed retrieval of local funds transfer details using an invalid idempotency key format via instaPay | F29: Send GET Request of Check Local Fund Transfer Details and Status API using invalid idempotency-key format via InstaPay | G29: Error response is returned 404 Not Found / 400 Bad Request Transaction details are not found responseCode responseDescription | H29: 400 | I29: Transaction not found for the provided idempotencyKey | J29: /send-funds/localft/v1/status | M29: 5500000000O00 | N29: 104234abc4 | O29: GsG5c0UhuhXUPj4XlY8G1kcjKioiFrqI | P29: application/json
A30: 29 | B30: =C30 -> Y | C30: Y | D30: TS-EB-PRODUCTS-0275 | E30: TS-EB-PRODUCTS-0275: Send Funds via Local Fund Transfer v1.0 _Check Local Funds Transfer Details and Status API_Verify failed retrieval of local funds transfer details using an invalid idempotency key format via PESONet | F30: Send GET Request of Check Local Fund Transfer Details and Status API using invalid idempotency-key format via PESONEt | G30: Error response is returned 404 Not Found / 400 Bad Request Transaction details are not found responseCode responseDescription | H30: 400 | I30: Transaction not found for the provided idempotencyKey | J30: /send-funds/localft/v1/status | M30: 400000P000000 | N30: 104234abc4 | O30: GsG5c0UhuhXUPj4XlY8G1kcjKioiFrqI | P30: application/json
A31: 30 | B31: =C31 -> Y | C31: Y | D31: TS-EB-PRODUCTS-0278 | E31: TS-EB-PRODUCTS-0278: Send Funds via Local Fund Transfer v1.0 _Check Local Funds Transfer Details and Status API_Verify failed GET request of Local Fund Transfer (Transaction Details) upon providing Invalid format API-Txn-ID via InstaPay | F31: Send GET Request of Check Local Fund Transfer Details and Status API using Invalid Format Transaction ID (API-Txn-ID) via InstaPay | G31: The API returns an error message: Status 400 Bad Request statusDescription | H31: 400 | I31: Transaction not found for the provided apiTxnId | J31: /send-funds/localft/v1/status | K31: 550 | N31: 104234abc4 | O31: GsG5c0UhuhXUPj4XlY8G1kcjKioiFrqI | P31: application/json
